<?xml version="1.0"?>

<robot name="sambot" xmlns:xacro="http://www.ros.org/wiki/xacro">
    <!-- <xacro:include filename="$(find sambot_description)/gazebo/sambot.gazebo" /> -->
    <xacro:arg name="model" default="sambot"/>

    <!-- Used for fixing robot to Gazebo 'base_link' -->
    <!-- <link name="world"/> -->

    <!-- <joint name="fixed" type="fixed">
      <parent link="world"/>
      <child link="chassis"/>
    </joint> -->

    <link name="chassis">
      <inertial>
        <mass value="15.0"/>
        <origin rpy="0 0 0" xyz="0 0 0"/>
        <inertia ixx="0.08025" ixy="0" ixz="0" iyy="0.08025" iyz="0" izz="0.1445"/>
      </inertial>

      <collision>
        <origin rpy="1.57079632679 0.0 1.57079632679" xyz="0.0 0.0 0.086"/>
        <geometry>
          <mesh filename="file://$(find sambot_description)/urdf/sambot_models/meshes/JetBot-v3-Chassis.dae" scale="0.002 0.002 0.002"/>
        </geometry>
      </collision>

      <visual>
        <origin rpy="1.57079632679 0.0 1.57079632679" xyz="0.0 0.0 0.086"/>
        <geometry>
          <mesh filename="file://$(find sambot_description)/urdf/sambot_models/meshes/JetBot-v3-Chassis.dae" scale="0.002 0.002 0.002"/>
        </geometry>
      </visual>
    </link>

  <link
    name="base_laser">
    <inertial>
      <origin
        xyz="-0.00029774 0.0066667 0.00013047"
        rpy="0 0 0" />
      <mass
        value="0.15717" />
      <inertia
        ixx="6.7885E-05"
        ixy="-1.3987E-07"
        ixz="-8.1554E-07"
        iyy="0.00013173"
        iyz="-9.0932E-08"
        izz="7.1972E-05" />
    </inertial>
    <visual>
        <origin rpy="0.0 0.0 0.0" xyz="0.0 0.0 0"/>

      <geometry>
        <mesh
          filename="file://$(find sambot_description)/urdf/sambot_models/meshes/ydlidar.dae" />
      </geometry>
      <material
        name="">
        <color
          rgba="0.64706 0.61961 0.58824 1" />
      </material>
    </visual>
    <collision>
        <origin rpy="0.0 0.0 0.0" xyz="0.0 0.0 0"/>

      <geometry>
        <mesh
          filename="file://$(find sambot_description)/urdf/sambot_models/meshes/ydlidar.dae" />
      </geometry>
    </collision>
  </link>

<link name='laser_platform'>
    <pose>0 0 0.1 0 0 0</pose>

    <inertial>
      <mass value="2.0"/>
      <origin xyz="0.0 0 0" rpy=" 0 0 0"/>
      <inertia
          ixx="0.1" ixy="0" ixz="0"
          iyy="0.1" iyz="0"
          izz="0.1"
      />
    </inertial>

    <collision name='collision'>
      <origin xyz="0 0 0" rpy=" 0 0 0"/> 
      <geometry>
        <box size=".18 .13 .01"/>
      </geometry>
    </collision>

    <visual name='visual'>
      <origin xyz="0 0 0" rpy=" 0 0 0"/>
      <geometry>
        <box size=".18 .13 .01" />
      </geometry>
    </visual>
</link>

<link name="laser_frame">
  <inertial>
    <origin xyz="-0.00036659 0.00064155 -0.00027052"
            rpy="0 0 0"/>
    <mass value="0.25482" />
      <inertia
        ixx="8.9194E-05"
        ixy="1.8116E-07"
        ixz="3.6435E-08"
        iyy="0.00018279"
        iyz="2.423E-07"
        izz="0.00011103"/>
    </inertial>
</link>

<joint
    name="laser_joint"
    type="fixed">
    <origin
      xyz="0 0 0.03172"
      rpy="0 0 0" />
    <parent
      link="base_laser" />
    <child
      link="laser_frame" />
    <axis
      xyz="0 0 0" />
  </joint>

<joint type="fixed" name="laser_platform_joint">
 <origin xyz="0.0 0 0.2" rpy="0 0 0"/>
 <child link="laser_platform"/>
 <parent link="chassis"/>
 <axis xyz="0 0 1" rpy="0 0 0"/>
 <limit effort="10000" velocity="1000"/>
 <dynamics damping="1.0" friction="1.0"/>
</joint>

<joint type="fixed" name="base_laser_joint">
 <origin xyz="0.0 0 0.21" rpy="0 0 0"/>
 <child link="base_laser"/>
 <parent link="chassis"/>
 <axis xyz="0 0 1" rpy="0 0 0"/>
 <limit effort="10000" velocity="1000"/>
 <dynamics damping="1.0" friction="1.0"/>
</joint>

    <link name="left_wheel">
      <inertial>
        <mass value="5"/>
        <origin rpy="0 0 0" xyz="0 0 0"/>
        <inertia ixx="0.000129167" ixy="0" ixz="0" iyy="0.000129167" iyz="0" izz="0.0000225"/>
      </inertial>

      <collision>
        <origin rpy="0 0 0" xyz="0 0 0"/>
        <geometry>
          <mesh filename="file://$(find sambot_description)/urdf/sambot_models/meshes/JetBot-v3-Wheel.stl" scale="0.002 0.002 0.002"/>
        </geometry>
      </collision>

      <visual>
        <origin rpy="0 0 0" xyz="0 0 0"/>
          <geometry>
            <mesh filename="file://$(find sambot_description)/urdf/sambot_models/meshes/JetBot-v3-Wheel.stl" scale="0.002 0.002 0.002"/>
          </geometry>
      </visual>
    </link>


    <joint name='front_left_wheel_joint' type='continuous'>
      <origin rpy="0.0 0.0 1.57079632679" xyz="0.06 0.1025 0.06"/>
      <child  link="left_wheel"/>
      <parent link="chassis"/>
      <axis rpy="0 0 0" xyz="1 0 0"/>
      <limit lower="-1e+16" upper="1e+16" effort="100" velocity="100"/>
    </joint>


    <link name="right_wheel">
      <inertial>
        <mass value="5"/>
        <origin rpy="0 0 0" xyz="0 0 0"/>
        <inertia ixx="0.000129167" ixy="0" ixz="0" iyy="0.000129167" iyz="0" izz="0.0000225"/>
      </inertial>

      <collision>
        <origin rpy="0 0 0" xyz="0 0 0"/>
        <geometry>
          <mesh filename="file://$(find sambot_description)/urdf/sambot_models/meshes/JetBot-v3-Wheel.stl" scale="0.002 0.002 0.002"/>
        </geometry>
      </collision>

      <visual>
        <origin rpy="0 0 0" xyz="0 0 0"/>
        <geometry>
          <mesh filename="file://$(find sambot_description)/urdf/sambot_models/meshes/JetBot-v3-Wheel.stl" scale="0.002 0.002 0.002"/>
        </geometry>
      </visual>
    </link>


    <joint name='front_right_wheel_joint' type='continuous'>
      <origin rpy="0.0 0.0 1.57079632679 " xyz="0.06 -0.119 0.06"/>
      <child  link="right_wheel"/>
      <parent link="chassis"/>
      <axis rpy="0 0 0" xyz="1 0 0"/>
      <limit lower="-1e+16" upper="1e+16" effort="100" velocity="100"/>
    </joint>


    <joint name="camera_joint" type="fixed">
      <origin rpy="0 0.25 0" xyz="0.11 0.0 0.1714"/>
      <child  link="camera"/>
      <parent link="chassis"/>
      <pose>0.0 0.0 0.0 0.0 0.0 0.0</pose>
      <axis>
        <xyz>0.1 0.0 0.0</xyz>
      </axis>
    </joint>


    <!-- Camera -->
    <link name="camera">
      <gravity>false</gravity>
      <inertial>
        <inertia ixx="0"  ixy="0"  ixz="0" iyy="0" iyz="0" izz="0" />
        <mass value="0.1"/>
      </inertial>
      <visual name="visual">
        <origin rpy="0 0 0" xyz="0 0.0 0"/>
        <geometry>
          <box size="0.002 0.002 0.002"/>
        </geometry>
      </visual>
    </link>


    <joint name="camera_optical_joint" type="fixed">
      <!-- these values have to be these values otherwise the gazebo camera image
          won't be aligned properly with the frame it is supposedly originating from -->
      <origin xyz="0 0 0" rpy="0 0 0"/>
      <parent link="camera"/>
      <child link="camera_link_optical"/>
    </joint>


    <link name="camera_link_optical">
    </link>


    <transmission name="front_left_wheel_transmission">
      <type>transmission_interface/SimpleTransmission</type>
      <joint name="front_left_wheel_joint">
        <hardwareInterface>hardware_interface/VelocityJointInterface</hardwareInterface>
      </joint>
      <actuator name="motor1">
        <hardwareInterface>hardware_interface/VelocityJointInterface</hardwareInterface>
        <mechanicalReduction>1</mechanicalReduction>
      </actuator>
    </transmission>


    <transmission name="front_right_wheel_transmission">
      <type>transmission_interface/SimpleTransmission</type>
      <joint name="front_right_wheel_joint">
        <hardwareInterface>hardware_interface/VelocityJointInterface</hardwareInterface>
      </joint>
      <actuator name="motor2">
        <hardwareInterface>hardware_interface/VelocityJointInterface</hardwareInterface>
        <mechanicalReduction>1</mechanicalReduction>
      </actuator>
    </transmission>

    <!-- IMU -->
    <joint name="imu_joint" type="fixed">
      <origin rpy="0 0 0" xyz="0.06 0.0 0.1714"/>
      <child  link="imu_link"/>
      <parent link="chassis"/>
      <pose>0.0 0.0 0.0 0.0 0.0 0.0</pose>
      <axis>
        <xyz>0.1 0.0 0.0</xyz>
      </axis>
    </joint>

    <link name="imu_link">
      <gravity>false</gravity>
      <inertial>
        <inertia ixx="0"  ixy="0"  ixz="0" iyy="0" iyz="0" izz="0" />
        <mass value="0.003"/>
      </inertial>
      <visual name="visual">
        <origin rpy="0 0 0" xyz="0 0.0 0"/>
        <geometry>
          <box size="0.002 0.002 0.002"/>
        </geometry>
      </visual>
    </link>

</robot>
